<?xml version="1.0" ?>
<sdf version="1.5">
  <world name="default">

    <!-- A global light source -->
    <include>
      <uri>model://sun</uri>
    </include>

    <!-- A ground plane -->
    <include>
      <uri>model://ground_plane</uri>
    </include>

    <!-- World plugin that publishes event messages -->
    <plugin filename="libSimEventsPlugin.so" name="elevator_event_plugin">
      <region>
        <name>region1</name>
        <volume>
          <min>140.0 61.0 0</min>
          <max>143.0 63.0 1</max>
        </volume>
      </region>
      <region>
        <name>region2</name>
        <volume>
          <min>140.0 61.0 3</min>
          <max>143.0 63.0 4</max>
        </volume>
      </region>
      <event>
        <name>region1_event</name>
        <type>occupied</type>
        <region>region1</region>
        <topic>~/elevator</topic>
        <msg_data>0</msg_data>
      </event>
      <event>
        <name>region2_event</name>
        <type>occupied</type>
        <region>region2</region>
        <topic>~/elevator</topic>
        <msg_data>1</msg_data>
      </event>
    </plugin>

    <!-- The elevator car -->
    <model name="elevator">
      <pose>141.50 64.73 0.075 0 0 -1.5708</pose>
      <link name="link">
        <inertial>
          <mass>800</mass>
        </inertial>
        <collision name="floor_collision">
          <geometry>
            <box>
              <size>2.25 2.25 0.15</size>
            </box>
          </geometry>
        </collision>
        <visual name="floor_visual">
          <geometry>
            <box>
              <size>2.25 2.25 0.15</size>
            </box>
          </geometry>
        </visual>
      </link>

      <link name="wall1">
        <pose>1.0745 0.5725 1.125 0 0 0</pose> 
        <collision name="collision">
          <geometry>
            <box>
              <size>0.1 1.15 2.25</size>
            </box>
          </geometry>
        </collision>
        <visual name="visual">
          <geometry>
            <box>
              <size>0.1 1.15 2.25</size>
            </box>
          </geometry>
          <material>
            <script>
              <name>Gazebo/Red</name>
            </script>
          </material>
        </visual>
      </link>

      <link name="wall2">
        <pose>1.0745 -1.0625 1.125 0 0 0</pose> 
        <collision name="collision">
          <geometry>
            <box>
              <size>0.1 0.125 2.25</size>
            </box>
          </geometry>
        </collision>
        <visual name="visual">
          <geometry>
            <box>
              <size>0.1 0.125 2.25</size>
            </box>
          </geometry>
          <material>
            <script>
              <name>Gazebo/Red</name>
            </script>
          </material>
        </visual>
      </link>

      <link name="door">
        <pose>1.0745 -0.5 1.125 0 0 0</pose> 
        <collision name="collision">
          <geometry>
            <box>
              <size>0.08 1.0 2.25</size>
            </box>
          </geometry>
        </collision>
        <visual name="visual">
          <geometry>
            <box>
              <size>0.08 1.0 2.25</size>
            </box>
          </geometry>
        </visual>
      </link>

      <joint name="wall1_joint" type="fixed">
        <parent>link</parent>
        <child>wall1</child>
      </joint>
      <joint name="wall2_joint" type="fixed">
        <parent>link</parent>
        <child>wall2</child>
      </joint>
      <joint name="door_joint" type="prismatic">
        <parent>link</parent>
        <child>door</child>
        <axis>
          <xyz>0 1 0</xyz>
          <limit>
            <lower>0</lower>
            <upper>1</upper>
            <effort>10</effort>
          </limit>
          <dynamics>
            <damping>2</damping>
          </dynamics>
        </axis>
      </joint>

      <joint name="lift_joint" type="prismatic">
        <parent>world</parent>
        <child>link</child>
        <axis>
          <xyz>0 0 1</xyz>
          <limit>
            <lower>0</lower>
            <upper>10</upper>
            <effort>100000</effort>
          </limit>
          <dynamics>
            <damping>50</damping>
          </dynamics>
        </axis>
        <physics>
          <ode>
            <implicit_spring_damper>1</implicit_spring_damper>
          </ode>
        </physics>
      </joint>

      <!-- Plugin to control the elevator -->
      <plugin filename="libElevatorPlugin.so" name="elevator_plugin">
        <lift_joint>elevator::lift_joint</lift_joint>
        <door_joint>elevator::door_joint</door_joint>
        <floor_height>3.075</floor_height>
        <door_wait_time>10</door_wait_time>
        <topic>~/elevator</topic>
      </plugin>
    </model>

    <model name="floor0">
      <pose>141.636 62.576 0.075 0 0 -1.5708</pose>
      <static>true</static>
      <link name="link">
        <collision name="floor_collision">
          <geometry>
            <box>
              <size>2.0 5.0 0.15</size>
            </box>
          </geometry>
        </collision>
        <visual name="floor_visual">
          <geometry>
            <box>
              <size>2.0 5.0 0.15</size>
            </box>
          </geometry>
        </visual>
      </link>
    </model>

    <model name="floor1">
      <pose>141.618 62.569 3.075 0 0 -1.5708</pose>
      <static>true</static>
      <link name="link">
        <collision name="floor_collision">
          <geometry>
            <box>
              <size>2.0 5.0 0.15</size>
            </box>
          </geometry>
        </collision>
        <visual name="floor_visual">
          <geometry>
            <box>
              <size>2.0 5.0 0.15</size>
            </box>
          </geometry>
        </visual>
      </link>
    </model>

  </world>
</sdf>
