<?xml version="1.0" ?>
<sdf version="1.6">
    <model name="joint_controller_demo">
      <pose>0 0 0 0 0 0</pose>
      <link name="base_link">
            <pose>0.0 0.0 0.0 0 0 0</pose>
            <inertial>
                <inertia>
                    <ixx>2.501</ixx>
                    <ixy>0</ixy>
                    <ixz>0</ixz>
                    <iyy>2.501</iyy>
                    <iyz>0</iyz>
                    <izz>5</izz>
                </inertia>
                <mass>120.0</mass>
            </inertial>
            <visual name="base_visual">
                <pose>0.0 0.0 0.0 0 0 0</pose>
                <geometry>
                    <box>
                    <size>0.5 0.5 0.01</size>
                    </box>
                </geometry>
            </visual>
            <collision name="base_collision">
                <pose>0.0 0.0 0.0 0 0 0</pose>
                <geometry>
                    <box>
                    <size>0.5 0.5 0.01</size>
                    </box>
                </geometry>
            </collision>
      </link>
      <link name="rotor">
            <pose>0.0 0.0 0.1 0 0 0</pose>
            <inertial>
            <inertia>
                <ixx>0.032</ixx>
                <ixy>0</ixy>
                <ixz>0</ixz>
                <iyy>0.032</iyy>
                <iyz>0</iyz>
                <izz>0.00012</izz>
            </inertia>
            <mass>0.6</mass>
            </inertial>
            <visual name="visual">
            <geometry>
                <box>
                <size>0.25 0.1 0.05</size>
                </box>
            </geometry>
            <material>
                <ambient>0.2 0.8 0.2 1</ambient>
                <diffuse>0.8 0 0 1</diffuse>
            </material>
            </visual>
            <collision name="collision">
            <geometry>
                <box>
                <size>0.25 0.1 0.05</size>
                </box>
            </geometry>
            </collision>
      </link>
 
      <joint name="world_fixed" type="fixed">
        <parent>world</parent>
        <child>base_link</child>
      </joint>
 
      <joint name="j1" type="revolute">
        <pose>0 0 -0.5 0 0 0</pose>
        <parent>base_link</parent>
        <child>rotor</child>
        <axis>
          <xyz>0 0 1</xyz>
        </axis>
      </joint>

        <plugin name="init_joint_control" filename="libJointControlPlugin.so">
            <controller type="position">
                <joint>j1</joint>
                <target>1.0</target>
                <pid_gains>5 0.1 0.01</pid_gains>
            </controller>
        </plugin>
    </model>
</sdf>
