<?xml version="1.0"?>
<robot name="door_robot">
  <!-- Door frame -->
  <link name="door_frame">
    <visual>
      <geometry>
        <box size="0.1 2.0 4.0"/>
      </geometry>
      <material name="grey">
        <color rgba="0.5 0.5 0.5 1.0"/>
      </material>
    </visual>
    <collision>
      <geometry>
        <box size="0.1 2.0 4.0"/>
      </geometry>
    </collision>
    <inertial>
      <mass value="10.0"/>
      <origin xyz="0 0 0"/>
      <inertia ixx="0.1" ixy="0.0" ixz="0.0" iyy="0.1" iyz="0.0" izz="0.1"/>
    </inertial>
  </link>

  <!-- Door panel -->
  <link name="door_panel">
    <visual>
      <geometry>
        <box size="0.1 2.0 4.0"/>
      </geometry>
      <material name="brown">
        <color rgba="0.4 0.2 0.1 1.0"/>
      </material>
    </visual>
    <collision>
      <geometry>
        <box size="0.1 2.0 4.0"/>
      </geometry>
    </collision>
    <inertial>
      <mass value="10.0"/>
      <origin xyz="0 0 0"/>
      <inertia ixx="0.1" ixy="0.0" ixz="0.0" iyy="0.1" iyz="0.0" izz="0.1"/>
    </inertial>
  </link>

  <!-- Joint connecting frame and panel -->
  <joint name="door_hinge" type="revolute">
    <parent link="door_frame"/>
    <child link="door_panel"/>
    <origin xyz="0 1 0" rpy="0 0 0"/>
    <axis xyz="0 0 1"/>
    <limit lower="-1.57" upper="1.57" effort="10.0" velocity="1.0"/>
    <dynamics damping="0.1" friction="0.1"/>
  </joint>
</robot>
